<robot name="test_pendulum">

  <material name="red">
    <color rgba="1 0 0 1"/>
  </material>

  <material name="blue">
    <color rgba="0 0 1 1"/>
  </material>

  <link name="base">
    <visual>
      <geometry>
        <box size="0.1 0.1 0.1"/>
      </geometry>
      <origin rpy="0.0 0.0 0.0" xyz="0.0 0.0 0.0"/>
      <material name="red"/>
    </visual>
    <inertial>
      <mass value="0.0"/>
      <origin rpy="0.0 0.0 0.0" xyz="0.0 0.0 0.0"/>
      <inertia ixx="0.0" iyy="0.0" izz="0.0" iyz="0.0" ixz="0.0" ixy="0.0"/>
    </inertial>
  </link>

  <link name="arm">
    <visual>
      <geometry>
        <box size="0.1 0.1 1"/>
      </geometry>
      <origin xyz="0.1 0.0 0.45" rpy="0.0 0.0 0.0"/>
      <material name="blue"/>
    </visual>
    <inertial>
      <mass value="10.0"/>
      <origin xyz="0.1 0.0 0.45" rpy="0.0 0.0 0.0"/>
      <!-- Beware of the mass origin relative to the joint -->
      <inertia ixx="0.0" iyy="0.0" izz="0.0" iyz="0.0" ixz="0.0" ixy="0.0"/>
    </inertial>
  </link>

  <joint name="joint1" type="continuous">
    <parent link="base"/>
    <child link="arm"/>
    <origin xyz="0.01 0 0" rpy="0 0 0" />
    <axis xyz="1 0 0" />
  </joint>

</robot>
