<robot name="robot">
  <link name="base_footprint"></link>
  <joint name="base_joint" type="fixed">
    <parent link="base_footprint" />
    <child link="base_link" />
    <origin xyz="0 0 4" rpy="0 0 0" />
  </joint>
  <link name="base_link">
    <visual>
      <origin xyz="0 0 0" rpy="0 0 0" />
      <geometry>
        <box size="1 3 1" />
      </geometry>
      <material name="base_link-material">
        <color rgba="0.08228270712149792 0.040915196900556984 0.6038273388475408 1" />
      </material>
    </visual>
    <collision>
      <origin xyz="0 0 0" rpy="0 0 0" />
      <geometry>
        <box size="1 3 1" />
      </geometry>
    </collision>
    <inertial>
      <origin xyz="0 0 0" rpy="0 0 0" />
      <mass value="100" />
      <inertia ixx="16.666666666666664" ixy="0" ixz="0" iyy="16.666666666666664" iyz="0" izz="16.666666666666664" />
    </inertial>
  </link>
  <joint name="base_link_to_hips_FR" type="revolute">
    <parent link="base_link" />
    <child link="hips_FR" />
    <origin xyz="1 1 0" rpy="0 0 0" />
    <axis xyz="0 0 1"/>
    <limit effort="1000.0" lower="-1" upper="1" velocity="0.5"/>  </joint>
  <link name="hips_FR">
    <visual>
      <origin xyz="0 0 0" rpy="0 0 0" />
      <geometry>
        <cylinder radius="0.5" length="1" />
      </geometry>
      <material name="hips_FR-material">
        <color rgba="0.21223075740342198 0.8069522576650873 0.009134058699157796 1" />
      </material>
    </visual>
    <collision>
      <origin xyz="0 0 0" rpy="0 0 0" />
      <geometry>
        <cylinder radius="0.5" length="1" />
      </geometry>
    </collision>
    <inertial>
      <origin xyz="0 0 0" rpy="0 0 0" />
      <mass value="1" />
      <inertia ixx="0.3333333333333333" ixy="0" ixz="0" iyy="0.5" iyz="0" izz="0.3333333333333333" />
    </inertial>
  </link>
  <joint name="hips_FR_to_femur_FR" type="fixed">
    <parent link="hips_FR" />
    <child link="femur_FR" />
    <origin xyz="0 0 -1" rpy="0 0 0" />
  </joint>
  <link name="femur_FR">
    <visual>
      <origin xyz="0 0 0" rpy="0 0 0" />
      <geometry>
        <box size="1 1 1" />
      </geometry>
      <material name="femur_FR-material">
        <color rgba="0.14126329113044458 0.6653872982754769 0.5271151256969157 1" />
      </material>
    </visual>
    <collision>
      <origin xyz="0 0 0" rpy="0 0 0" />
      <geometry>
        <box size="1 1 1" />
      </geometry>
    </collision>
    <inertial>
      <origin xyz="0 0 0" rpy="0 0 0" />
      <mass value="1" />
      <inertia ixx="0.16666666666666666" ixy="0" ixz="0" iyy="0.16666666666666666" iyz="0" izz="0.16666666666666666" />
    </inertial>
  </link>
  <joint name="femur_FR_to_knee_FR" type="revolute">
    <parent link="femur_FR" />
    <child link="knee_FR" />
    <origin xyz="0 1 0" rpy="-3.141592653589793 NaN -3.141592653589793" />
    <axis xyz="0 0 1"/>
    <limit effort="1000.0" lower="-2" upper="0" velocity="0.5"/>  </joint>
  <link name="knee_FR">
    <visual>
      <origin xyz="2.220446049250313e-15 0 0" rpy="0 0 0" />
      <geometry>
        <cylinder radius="0.5" length="1" />
      </geometry>
      <material name="knee_FR-material">
        <color rgba="0.22696587349938613 0.012286488353353374 0.0009105809505882353 1" />
      </material>
    </visual>
    <collision>
      <origin xyz="2.220446049250313e-15 0 0" rpy="0 0 0" />
      <geometry>
        <cylinder radius="0.5" length="1" />
      </geometry>
    </collision>
    <inertial>
      <origin xyz="2.220446049250313e-15 0 0" rpy="0 0 0" />
      <mass value="1" />
      <inertia ixx="0.3333333333333333" ixy="0" ixz="0" iyy="0.5" iyz="0" izz="0.3333333333333333" />
    </inertial>
  </link>
  <joint name="knee_FR_to_leg_FR" type="fixed">
    <parent link="knee_FR" />
    <child link="leg_FR" />
    <origin xyz="0 3 0" rpy="3.141592653589793 -1.5707963267948966 3.141592653589793" />
  </joint>
  <link name="leg_FR">
    <visual>
      <origin xyz="0 0 0" rpy="0 0 0" />
      <geometry>
        <box size="1 5 1" />
      </geometry>
      <material name="leg_FR-material">
        <color rgba="0.040915196900556984 0.04373502925049377 0.007499032040460618 1" />
      </material>
    </visual>
    <collision>
      <origin xyz="0 0 0" rpy="0 0 0" />
      <geometry>
        <box size="1 5 1" />
      </geometry>
    </collision>
    <inertial>
      <origin xyz="0 0 0" rpy="0 0 0" />
      <mass value="1" />
      <inertia ixx="0.16666666666666666" ixy="0" ixz="0" iyy="0.16666666666666666" iyz="0" izz="0.16666666666666666" />
    </inertial>
  </link>
  <joint name="leg_FR_to_wheel_FR" type="continuous">
    <parent link="leg_FR" />
    <child link="wheel_FR" />
    <origin xyz="0.6 2 0" rpy="-3.141592653589793 NaN -3.141592653589793" />
    <axis xyz="0 0 1"/>
  </joint>
  <link name="wheel_FR">
    <visual>
      <origin xyz="0 0 0" rpy="0 0 0" />
      <geometry>
        <cylinder radius="2" length="0.2" />
      </geometry>
      <material name="wheel_FR-material">
        <color rgba="0.023153366173251363 0.00972121731707524 0.24228112245478564 1" />
      </material>
    </visual>
    <collision>
      <origin xyz="0 0 0" rpy="0 0 0" />
      <geometry>
        <cylinder radius="2" length="0.2" />
      </geometry>
    </collision>
    <inertial>
      <origin xyz="0 0 0" rpy="0 0 0" />
      <mass value="1" />
      <inertia ixx="0.3333333333333333" ixy="0" ixz="0" iyy="0.5" iyz="0" izz="0.3333333333333333" />
    </inertial>
  </link>
  <joint name="base_link_to_hips_FL" type="revolute">
    <parent link="base_link" />
    <child link="hips_FL" />
    <origin xyz="-1 1 0" rpy="0 0 0" />
    <axis xyz="0 0 1"/>
    <limit effort="1000.0" lower="-1" upper="1" velocity="0.5"/>  </joint>
  <link name="hips_FL">
    <visual>
      <origin xyz="0 0 0" rpy="0 0 0" />
      <geometry>
        <cylinder radius="0.5" length="1" />
      </geometry>
      <material name="hips_FL-material">
        <color rgba="0.21223075740342198 0.8069522576650873 0.009134058699157796 1" />
      </material>
    </visual>
    <collision>
      <origin xyz="0 0 0" rpy="0 0 0" />
      <geometry>
        <cylinder radius="0.5" length="1" />
      </geometry>
    </collision>
    <inertial>
      <origin xyz="0 0 0" rpy="0 0 0" />
      <mass value="1" />
      <inertia ixx="0.3333333333333333" ixy="0" ixz="0" iyy="0.5" iyz="0" izz="0.3333333333333333" />
    </inertial>
  </link>
  <joint name="hips_FL_to_femur_FL" type="fixed">
    <parent link="hips_FL" />
    <child link="femur_FL" />
    <origin xyz="0 0 -1" rpy="0 0 0" />
  </joint>
  <link name="femur_FL">
    <visual>
      <origin xyz="0 0 0" rpy="0 0 0" />
      <geometry>
        <box size="1 1 1" />
      </geometry>
      <material name="femur_FL-material">
        <color rgba="0.14126329113044458 0.6653872982754769 0.5271151256969157 1" />
      </material>
    </visual>
    <collision>
      <origin xyz="0 0 0" rpy="0 0 0" />
      <geometry>
        <box size="1 1 1" />
      </geometry>
    </collision>
    <inertial>
      <origin xyz="0 0 0" rpy="0 0 0" />
      <mass value="1" />
      <inertia ixx="0.16666666666666666" ixy="0" ixz="0" iyy="0.16666666666666666" iyz="0" izz="0.16666666666666666" />
    </inertial>
  </link>
  <joint name="femur_FL_to_knee_FL" type="revolute">
    <parent link="femur_FL" />
    <child link="knee_FL" />
    <origin xyz="0 1 0" rpy="-3.141592653589793 NaN -3.141592653589793" />
    <axis xyz="0 0 1"/>
    <limit effort="1000.0" lower="-2" upper="0" velocity="0.5"/>  </joint>
  <link name="knee_FL">
    <visual>
      <origin xyz="0 0 0" rpy="0 0 0" />
      <geometry>
        <cylinder radius="0.5" length="1" />
      </geometry>
      <material name="knee_FL-material">
        <color rgba="0.22696587349938613 0.012286488353353374 0.0009105809505882353 1" />
      </material>
    </visual>
    <collision>
      <origin xyz="0 0 0" rpy="0 0 0" />
      <geometry>
        <cylinder radius="0.5" length="1" />
      </geometry>
    </collision>
    <inertial>
      <origin xyz="0 0 0" rpy="0 0 0" />
      <mass value="1" />
      <inertia ixx="0.3333333333333333" ixy="0" ixz="0" iyy="0.5" iyz="0" izz="0.3333333333333333" />
    </inertial>
  </link>
  <joint name="knee_FL_to_leg_FL" type="fixed">
    <parent link="knee_FL" />
    <child link="leg_FL" />
    <origin xyz="0 3 0" rpy="3.141592653589793 NaN 3.141592653589793" />
  </joint>
  <link name="leg_FL">
    <visual>
      <origin xyz="0 0 0" rpy="0 0 0" />
      <geometry>
        <box size="1 5 1" />
      </geometry>
      <material name="leg_FL-material">
        <color rgba="0.040915196900556984 0.04373502925049377 0.007499032040460618 1" />
      </material>
    </visual>
    <collision>
      <origin xyz="0 0 0" rpy="0 0 0" />
      <geometry>
        <box size="1 5 1" />
      </geometry>
    </collision>
    <inertial>
      <origin xyz="0 0 0" rpy="0 0 0" />
      <mass value="1" />
      <inertia ixx="0.16666666666666666" ixy="0" ixz="0" iyy="0.16666666666666666" iyz="0" izz="0.16666666666666666" />
    </inertial>
  </link>
  <joint name="leg_FL_to_wheel_FL" type="continuous">
    <parent link="leg_FL" />
    <child link="wheel_FL" />
    <origin xyz="-0.6 2 0" rpy="-3.141592653589793 NaN -3.141592653589793" />
    <axis xyz="0 0 1"/>
  </joint>
  <link name="wheel_FL">
    <visual>
      <origin xyz="0 0 0" rpy="0 0 0" />
      <geometry>
        <cylinder radius="2" length="0.2" />
      </geometry>
      <material name="wheel_FL-material">
        <color rgba="0.023153366173251363 0.00972121731707524 0.24228112245478564 1" />
      </material>
    </visual>
    <collision>
      <origin xyz="0 0 0" rpy="0 0 0" />
      <geometry>
        <cylinder radius="2" length="0.2" />
      </geometry>
    </collision>
    <inertial>
      <origin xyz="0 0 0" rpy="0 0 0" />
      <mass value="1" />
      <inertia ixx="0.3333333333333333" ixy="0" ixz="0" iyy="0.5" iyz="0" izz="0.3333333333333333" />
    </inertial>
  </link>
  <joint name="base_link_to_hips_BL" type="revolute">
    <parent link="base_link" />
    <child link="hips_BL" />
    <origin xyz="-1 -1 0" rpy="0 0 3.141592653589793" />
    <axis xyz="0 0 1"/>
    <limit effort="1000.0" lower="-1" upper="1" velocity="0.5"/>  </joint>
  <link name="hips_BL">
    <visual>
      <origin xyz="0 0 0" rpy="0 0 0" />
      <geometry>
        <cylinder radius="0.5" length="1" />
      </geometry>
      <material name="hips_BL-material">
        <color rgba="0.21223075740342198 0.8069522576650873 0.009134058699157796 1" />
      </material>
    </visual>
    <collision>
      <origin xyz="0 0 0" rpy="0 0 0" />
      <geometry>
        <cylinder radius="0.5" length="1" />
      </geometry>
    </collision>
    <inertial>
      <origin xyz="0 0 0" rpy="0 0 0" />
      <mass value="1" />
      <inertia ixx="0.3333333333333333" ixy="0" ixz="0" iyy="0.5" iyz="0" izz="0.3333333333333333" />
    </inertial>
  </link>
  <joint name="hips_BL_to_femur_BL" type="fixed">
    <parent link="hips_BL" />
    <child link="femur_BL" />
    <origin xyz="0 0 -1" rpy="0 0 0" />
  </joint>
  <link name="femur_BL">
    <visual>
      <origin xyz="0 0 0" rpy="0 0 0" />
      <geometry>
        <box size="1 1 1" />
      </geometry>
      <material name="femur_BL-material">
        <color rgba="0.14126329113044458 0.6653872982754769 0.5271151256969157 1" />
      </material>
    </visual>
    <collision>
      <origin xyz="0 0 0" rpy="0 0 0" />
      <geometry>
        <box size="1 1 1" />
      </geometry>
    </collision>
    <inertial>
      <origin xyz="0 0 0" rpy="0 0 0" />
      <mass value="1" />
      <inertia ixx="0.16666666666666666" ixy="0" ixz="0" iyy="0.16666666666666666" iyz="0" izz="0.16666666666666666" />
    </inertial>
  </link>
  <joint name="femur_BL_to_knee_BL" type="revolute">
    <parent link="femur_BL" />
    <child link="knee_BL" />
    <origin xyz="0 1 0" rpy="-3.141592653589793 NaN -3.141592653589793" />
    <axis xyz="0 0 1"/>
    <limit effort="1000.0" lower="-2" upper="0" velocity="0.5"/>  </joint>
  <link name="knee_BL">
    <visual>
      <origin xyz="0 0 0" rpy="0 0 0" />
      <geometry>
        <cylinder radius="0.5" length="1" />
      </geometry>
      <material name="knee_BL-material">
        <color rgba="0.22696587349938613 0.012286488353353374 0.0009105809505882353 1" />
      </material>
    </visual>
    <collision>
      <origin xyz="0 0 0" rpy="0 0 0" />
      <geometry>
        <cylinder radius="0.5" length="1" />
      </geometry>
    </collision>
    <inertial>
      <origin xyz="0 0 0" rpy="0 0 0" />
      <mass value="1" />
      <inertia ixx="0.3333333333333333" ixy="0" ixz="0" iyy="0.5" iyz="0" izz="0.3333333333333333" />
    </inertial>
  </link>
  <joint name="knee_BL_to_leg_BL" type="fixed">
    <parent link="knee_BL" />
    <child link="leg_BL" />
    <origin xyz="0 3 0" rpy="3.141592653589793 NaN 3.141592653589793" />
  </joint>
  <link name="leg_BL">
    <visual>
      <origin xyz="0 0 0" rpy="0 0 0" />
      <geometry>
        <box size="1 5 1" />
      </geometry>
      <material name="leg_BL-material">
        <color rgba="0.040915196900556984 0.04373502925049377 0.007499032040460618 1" />
      </material>
    </visual>
    <collision>
      <origin xyz="0 0 0" rpy="0 0 0" />
      <geometry>
        <box size="1 5 1" />
      </geometry>
    </collision>
    <inertial>
      <origin xyz="0 0 0" rpy="0 0 0" />
      <mass value="1" />
      <inertia ixx="0.16666666666666666" ixy="0" ixz="0" iyy="0.16666666666666666" iyz="0" izz="0.16666666666666666" />
    </inertial>
  </link>
  <joint name="leg_BL_to_wheel_BL" type="continuous">
    <parent link="leg_BL" />
    <child link="wheel_BL" />
    <origin xyz="0.6 2 0" rpy="-3.141592653589793 NaN -3.141592653589793" />
    <axis xyz="0 0 1"/>
  </joint>
  <link name="wheel_BL">
    <visual>
      <origin xyz="0 0 0" rpy="0 0 0" />
      <geometry>
        <cylinder radius="2" length="0.2" />
      </geometry>
      <material name="wheel_BL-material">
        <color rgba="0.023153366173251363 0.00972121731707524 0.24228112245478564 1" />
      </material>
    </visual>
    <collision>
      <origin xyz="0 0 0" rpy="0 0 0" />
      <geometry>
        <cylinder radius="2" length="0.2" />
      </geometry>
    </collision>
    <inertial>
      <origin xyz="0 0 0" rpy="0 0 0" />
      <mass value="1" />
      <inertia ixx="0.3333333333333333" ixy="0" ixz="0" iyy="0.5" iyz="0" izz="0.3333333333333333" />
    </inertial>
  </link>
  <joint name="base_link_to_hips_BR" type="revolute">
    <parent link="base_link" />
    <child link="hips_BR" />
    <origin xyz="1 -1 0" rpy="0 0 3.141592653589793" />
    <axis xyz="0 0 1"/>
    <limit effort="1000.0" lower="-1" upper="1" velocity="0.5"/>  </joint>
  <link name="hips_BR">
    <visual>
      <origin xyz="0 0 0" rpy="0 0 0" />
      <geometry>
        <cylinder radius="0.5" length="1" />
      </geometry>
      <material name="hips_BR-material">
        <color rgba="0.21223075740342198 0.8069522576650873 0.009134058699157796 1" />
      </material>
    </visual>
    <collision>
      <origin xyz="0 0 0" rpy="0 0 0" />
      <geometry>
        <cylinder radius="0.5" length="1" />
      </geometry>
    </collision>
    <inertial>
      <origin xyz="0 0 0" rpy="0 0 0" />
      <mass value="1" />
      <inertia ixx="0.3333333333333333" ixy="0" ixz="0" iyy="0.5" iyz="0" izz="0.3333333333333333" />
    </inertial>
  </link>
  <joint name="hips_BR_to_femur_BR" type="fixed">
    <parent link="hips_BR" />
    <child link="femur_BR" />
    <origin xyz="0 0 -1" rpy="0 0 0" />
  </joint>
  <link name="femur_BR">
    <visual>
      <origin xyz="0 0 0" rpy="0 0 0" />
      <geometry>
        <box size="1 1 1" />
      </geometry>
      <material name="femur_BR-material">
        <color rgba="0.14126329113044458 0.6653872982754769 0.5271151256969157 1" />
      </material>
    </visual>
    <collision>
      <origin xyz="0 0 0" rpy="0 0 0" />
      <geometry>
        <box size="1 1 1" />
      </geometry>
    </collision>
    <inertial>
      <origin xyz="0 0 0" rpy="0 0 0" />
      <mass value="1" />
      <inertia ixx="0.16666666666666666" ixy="0" ixz="0" iyy="0.16666666666666666" iyz="0" izz="0.16666666666666666" />
    </inertial>
  </link>
  <joint name="femur_BR_to_knee_BR" type="revolute">
    <parent link="femur_BR" />
    <child link="knee_BR" />
    <origin xyz="0 1 0" rpy="-3.141592653589793 NaN -3.141592653589793" />
    <axis xyz="0 0 1"/>
    <limit effort="1000.0" lower="-2" upper="0" velocity="0.5"/>  </joint>
  <link name="knee_BR">
    <visual>
      <origin xyz="0 0 0" rpy="0 0 0" />
      <geometry>
        <cylinder radius="0.5" length="1" />
      </geometry>
      <material name="knee_BR-material">
        <color rgba="0.22696587349938613 0.012286488353353374 0.0009105809505882353 1" />
      </material>
    </visual>
    <collision>
      <origin xyz="0 0 0" rpy="0 0 0" />
      <geometry>
        <cylinder radius="0.5" length="1" />
      </geometry>
    </collision>
    <inertial>
      <origin xyz="0 0 0" rpy="0 0 0" />
      <mass value="1" />
      <inertia ixx="0.3333333333333333" ixy="0" ixz="0" iyy="0.5" iyz="0" izz="0.3333333333333333" />
    </inertial>
  </link>
  <joint name="knee_BR_to_leg_BR" type="fixed">
    <parent link="knee_BR" />
    <child link="leg_BR" />
    <origin xyz="0 3 0" rpy="3.141592653589793 NaN 3.141592653589793" />
  </joint>
  <link name="leg_BR">
    <visual>
      <origin xyz="0 0 0" rpy="0 0 0" />
      <geometry>
        <box size="1 5 1" />
      </geometry>
      <material name="leg_BR-material">
        <color rgba="0.040915196900556984 0.04373502925049377 0.007499032040460618 1" />
      </material>
    </visual>
    <collision>
      <origin xyz="0 0 0" rpy="0 0 0" />
      <geometry>
        <box size="1 5 1" />
      </geometry>
    </collision>
    <inertial>
      <origin xyz="0 0 0" rpy="0 0 0" />
      <mass value="1" />
      <inertia ixx="0.16666666666666666" ixy="0" ixz="0" iyy="0.16666666666666666" iyz="0" izz="0.16666666666666666" />
    </inertial>
  </link>
  <joint name="leg_BR_to_wheel_BR" type="continuous">
    <parent link="leg_BR" />
    <child link="wheel_BR" />
    <origin xyz="-0.6 2 0" rpy="-3.141592653589793 NaN -3.141592653589793" />
    <axis xyz="0 0 1"/>
  </joint>
  <link name="wheel_BR">
    <visual>
      <origin xyz="0 0 0" rpy="0 0 0" />
      <geometry>
        <cylinder radius="2" length="0.2" />
      </geometry>
      <material name="wheel_BR-material">
        <color rgba="0.023153366173251363 0.00972121731707524 0.24228112245478564 1" />
      </material>
    </visual>
    <collision>
      <origin xyz="0 0 0" rpy="0 0 0" />
      <geometry>
        <cylinder radius="2" length="0.2" />
      </geometry>
    </collision>
    <inertial>
      <origin xyz="0 0 0" rpy="0 0 0" />
      <mass value="1" />
      <inertia ixx="0.3333333333333333" ixy="0" ixz="0" iyy="0.5" iyz="0" izz="0.3333333333333333" />
    </inertial>
  </link>
</robot>