<robot name="robot">
  <link name="base_footprint"></link>
  <joint name="base_joint" type="fixed">
    <parent link="base_footprint" />
    <child link="base_link" />
    <origin xyz="0 0 1.7" rpy="0 0 0" />
  </joint>

  <link name="base_link">
    <visual>
      <origin xyz="0 0 0" rpy="0 0 0" />
      <geometry>
        <box size="2.5 0.75 0.1" />
      </geometry>
      <material name="base_link-material">
        <color rgba="0.46207699964472876 0.026241221889696346 0.5711248294565854 1" />
      </material>
    </visual>
    <collision>
      <origin xyz="0 0 0" rpy="0 0 0" />
      <geometry>
        <box size="2.5 0.75 0.1" />
      </geometry>
    </collision>
    <inertial>
      <origin xyz="0 0 0" rpy="0 0 0" />
      <mass value="100" />
      <inertia ixx="10" ixy="0" ixz="0" iyy="10" iyz="0" izz="10" />
    </inertial>
  </link>

  <joint name="base_link_to_hipFL" type="fixed">
    <parent link="base_link" />
    <child link="hipFL" />
    <origin xyz="1 0.45 -0.2" rpy="0 0 0" />
  </joint>

  <link name="hipFL">
    <visual>
      <origin xyz="0 0 0" rpy="0 0 0" />
      <geometry>
        <box size="0.1 0.1 0.5" />
      </geometry>
      <material name="hipFL-material">
        <color rgba="0.12213877222015301 0.3515325994898463 0.8227857543924378 1" />
      </material>
    </visual>
    <collision>
      <origin xyz="0 0 0" rpy="0 0 0" />
      <geometry>
        <box size="0.1 0.1 0.5" />
      </geometry>
    </collision>
    <inertial>
      <origin xyz="0 0 0" rpy="0 0 0" />
      <mass value="1" />
      <inertia ixx="0.16666666666666666" ixy="0" ixz="0" iyy="0.16666666666666666" iyz="0" izz="0.16666666666666666" />
    </inertial>
  </link>

  <joint name="hipFL_to_legFL" type="prismatic">
    <parent link="hipFL" />
    <child link="legFL" />
    <origin xyz="0 0 -0.5" rpy="0 0 0" />
    <axis xyz="0 0 1"/>
    <limit lower="-1" upper="1"/>
  </joint>

  <link name="legFL">
    <visual>
      <origin xyz="0 0 0" rpy="0 0 0" />
      <geometry>
        <box size="0.1 0.1 0.5" />
      </geometry>
      <material name="legFL-material">
        <color rgba="0.5209955731953768 0.6104955708001716 0.16513219449147767 1" />
      </material>
    </visual>
    <collision>
      <origin xyz="0 0 0" rpy="0 0 0" />
      <geometry>
        <box size="0.1 0.1 0.5" />
      </geometry>
    </collision>
    <inertial>
      <origin xyz="0 0 0" rpy="0 0 0" />
      <mass value="1" />
      <inertia ixx="0.16666666666666666" ixy="0" ixz="0" iyy="0.16666666666666666" iyz="0" izz="0.16666666666666666" />
    </inertial>
  </link>

  <joint name="legFL_to_feetFL" type="revolute">
    <parent link="legFL" />
    <child link="feetFL" />
    <origin xyz="0 0 -0.45" rpy="0 0 0" />
    <axis xyz="0 0 1"/>
    <limit effort="1000.0" lower="-1" upper="1" velocity="0.5"/>
  </joint>

  <link name="feetFL">
    <visual>
      <origin xyz="0 0 0" rpy="0 0 0" />
      <geometry>
        <box size="0.1 0.1 0.4" />
      </geometry>
      <material name="feetFL-material">
        <color rgba="0.04817182422013895 0.05286064701616471 0.06480326668529614 1" />
      </material>
    </visual>
    <inertial>
      <origin xyz="0 0 0" rpy="0 0 0" />
      <mass value="1" />
      <inertia ixx="0.16666666666666666" ixy="0" ixz="0" iyy="0.16666666666666666" iyz="0" izz="0.16666666666666666" />
    </inertial>
  </link>

  <joint name="feetFL_to_wheelFL" type="revolute">
    <parent link="feetFL" />
    <child link="wheelFL" />
    <origin xyz="0 0 -0.2" rpy="1.5707963267948963 0 0" />
    <axis xyz="0 0 1"/>
    <limit />
  </joint>

  <link name="wheelFL">
    <visual>
      <origin xyz="0 0 0" rpy="0 0 0" />
      <geometry>
        <cylinder radius="0.3" length="0.05" />
      </geometry>
      <material name="wheelFL-material">
        <color rgba="0.004024717016506897 0.012286488353353374 0.8069522576650873 1" />
      </material>
    </visual>
    <collision>
      <origin xyz="0 0 0" rpy="0 0 0" />
      <geometry>
        <cylinder radius="0.3" length="0.05" />
      </geometry>
    </collision>
    <inertial>
      <origin xyz="0 0 0" rpy="0 0 0" />
      <mass value="1" />
      <inertia ixx="0.3333333333333333" ixy="0" ixz="0" iyy="0.5" iyz="0" izz="0.3333333333333333" />
    </inertial>
  </link>

  <joint name="base_link_to_hipFR" type="fixed">
    <parent link="base_link" />
    <child link="hipFR" />
    <origin xyz="1 -0.45 -0.2" rpy="0 0 0" />
  </joint>

  <link name="hipFR">
    <visual>
      <origin xyz="0 0 0" rpy="0 0 0" />
      <geometry>
        <box size="0.1 0.1 0.5" />
      </geometry>
      <material name="hipFR-material">
        <color rgba="0.12213877222015301 0.3515325994898463 0.8227857543924378 1" />
      </material>
    </visual>
    <collision>
      <origin xyz="0 0 0" rpy="0 0 0" />
      <geometry>
        <box size="0.1 0.1 0.5" />
      </geometry>
    </collision>
    <inertial>
      <origin xyz="0 0 0" rpy="0 0 0" />
      <mass value="1" />
      <inertia ixx="0.16666666666666666" ixy="0" ixz="0" iyy="0.16666666666666666" iyz="0" izz="0.16666666666666666" />
    </inertial>
  </link>

  <joint name="hipFR_to_legFR" type="prismatic">
    <parent link="hipFR" />
    <child link="legFR" />
    <origin xyz="0 0 -0.5" rpy="0 0 0" />
    <axis xyz="0 0 1"/>
    <limit lower="-1" upper="1"/>
  </joint>

  <link name="legFR">
    <visual>
      <origin xyz="0 0 0" rpy="0 0 0" />
      <geometry>
        <box size="0.1 0.1 0.5" />
      </geometry>
      <material name="legFR-material">
        <color rgba="0.5209955731953768 0.6104955708001716 0.16513219449147767 1" />
      </material>
    </visual>
    <collision>
      <origin xyz="0 0 0" rpy="0 0 0" />
      <geometry>
        <box size="0.1 0.1 0.5" />
      </geometry>
    </collision>
    <inertial>
      <origin xyz="0 0 0" rpy="0 0 0" />
      <mass value="1" />
      <inertia ixx="0.16666666666666666" ixy="0" ixz="0" iyy="0.16666666666666666" iyz="0" izz="0.16666666666666666" />
    </inertial>
  </link>

  <joint name="legFR_to_feetFR" type="revolute">
    <parent link="legFR" />
    <child link="feetFR" />
    <origin xyz="0 0 -0.45" rpy="0 0 0" />
    <axis xyz="0 0 1"/>
    <limit effort="1000.0" lower="-1" upper="1" velocity="0.5"/>
  </joint>

  <link name="feetFR">
    <visual>
      <origin xyz="0 0 0" rpy="0 0 0" />
      <geometry>
        <box size="0.1 0.1 0.4" />
      </geometry>
      <material name="feetFR-material">
        <color rgba="0.04817182422013895 0.05286064701616471 0.06480326668529614 1" />
      </material>
    </visual>
    <inertial>
      <origin xyz="0 0 0" rpy="0 0 0" />
      <mass value="1" />
      <inertia ixx="0.16666666666666666" ixy="0" ixz="0" iyy="0.16666666666666666" iyz="0" izz="0.16666666666666666" />
    </inertial>
  </link>

  <joint name="feetFR_to_wheelFR" type="revolute">
    <parent link="feetFR" />
    <child link="wheelFR" />
    <origin xyz="0 0 -0.2" rpy="1.5707963267948963 0 0" />
    <axis xyz="0 0 1"/>
    <limit />
  </joint>

  <link name="wheelFR">
    <visual>
      <origin xyz="0 0 0" rpy="0 0 0" />
      <geometry>
        <cylinder radius="0.3" length="0.05" />
      </geometry>
      <material name="wheelFR-material">
        <color rgba="0.004024717016506897 0.012286488353353374 0.8069522576650873 1" />
      </material>
    </visual>
    <collision>
      <origin xyz="0 0 0" rpy="0 0 0" />
      <geometry>
        <cylinder radius="0.3" length="0.05" />
      </geometry>
    </collision>
    <inertial>
      <origin xyz="0 0 0" rpy="0 0 0" />
      <mass value="1" />
      <inertia ixx="0.3333333333333333" ixy="0" ixz="0" iyy="0.5" iyz="0" izz="0.3333333333333333" />
    </inertial>
  </link>

  <joint name="base_link_to_hipB" type="fixed">
    <parent link="base_link" />
    <child link="hipB" />
    <origin xyz="-1 0 -0.2" rpy="0 0 0" />
  </joint>

  <link name="hipB">
    <visual>
      <origin xyz="0 0 0" rpy="0 0 0" />
      <geometry>
        <box size="0.1 0.1 0.5" />
      </geometry>
      <material name="hipB-material">
        <color rgba="0.12213877222015301 0.3515325994898463 0.8227857543924378 1" />
      </material>
    </visual>
    <collision>
      <origin xyz="0 0 0" rpy="0 0 0" />
      <geometry>
        <box size="0.1 0.1 0.5" />
      </geometry>
    </collision>
    <inertial>
      <origin xyz="0 0 0" rpy="0 0 0" />
      <mass value="1" />
      <inertia ixx="0.16666666666666666" ixy="0" ixz="0" iyy="0.16666666666666666" iyz="0" izz="0.16666666666666666" />
    </inertial>
  </link>

  <joint name="hipB_to_legB" type="fixed">
    <parent link="hipB" />
    <child link="legB" />
    <origin xyz="0 0 -0.5" rpy="0 0 0" />
  </joint>

  <link name="legB">
    <visual>
      <origin xyz="0 0 0" rpy="0 0 0" />
      <geometry>
        <box size="0.1 0.1 0.5" />
      </geometry>
      <material name="legB-material">
        <color rgba="0.5209955731953768 0.6104955708001716 0.16513219449147767 1" />
      </material>
    </visual>
    <collision>
      <origin xyz="0 0 0" rpy="0 0 0" />
      <geometry>
        <box size="0.1 0.1 0.5" />
      </geometry>
    </collision>
    <inertial>
      <origin xyz="0 0 0" rpy="0 0 0" />
      <mass value="1" />
      <inertia ixx="0.16666666666666666" ixy="0" ixz="0" iyy="0.16666666666666666" iyz="0" izz="0.16666666666666666" />
    </inertial>
  </link>

  <joint name="legB_to_feetB" type="fixed">
    <parent link="legB" />
    <child link="feetB" />
    <origin xyz="0 0 -0.45" rpy="0 0 0" />
  </joint>

  <link name="feetB">
    <visual>
      <origin xyz="0 0 0" rpy="0 0 0" />
      <geometry>
        <box size="0.1 0.1 0.4" />
      </geometry>
      <material name="feetB-material">
        <color rgba="0.04817182422013895 0.05286064701616471 0.06480326668529614 1" />
      </material>
    </visual>
    <inertial>
      <origin xyz="0 0 0" rpy="0 0 0" />
      <mass value="1" />
      <inertia ixx="0.16666666666666666" ixy="0" ixz="0" iyy="0.16666666666666666" iyz="0" izz="0.16666666666666666" />
    </inertial>
  </link>

  <joint name="feetB_to_wheelB" type="revolute">
    <parent link="feetB" />
    <child link="wheelB" />
    <origin xyz="0 0 -0.2" rpy="1.5707963267948963 0 0" />
    <axis xyz="0 0 1"/>
    <limit />
  </joint>

  <link name="wheelB">
    <visual>
      <origin xyz="0 0 0" rpy="0 0 0" />
      <geometry>
        <cylinder radius="0.3" length="0.05" />
      </geometry>
      <material name="wheelB-material">
        <color rgba="0.004024717016506897 0.012286488353353374 0.8069522576650873 1" />
      </material>
    </visual>
    <collision>
      <origin xyz="0 0 0" rpy="0 0 0" />
      <geometry>
        <cylinder radius="0.3" length="0.05" />
      </geometry>
    </collision>
    <inertial>
      <origin xyz="0 0 0" rpy="0 0 0" />
      <mass value="1" />
      <inertia ixx="0.3333333333333333" ixy="0" ixz="0" iyy="0.5" iyz="0" izz="0.3333333333333333" />
    </inertial>
  </link>
</robot>