

<robot name="robot">
  <link name="base_footprint"></link>
  <joint name="base_joint" type="fixed">
    <parent link="base_footprint" />
    <child link="base_link" />
    <origin xyz="0 0 1" rpy="0 0 0" />
  </joint>

  <link name="base_link">
    <visual>
      <origin xyz="0 0 0" rpy="0 0 0" />
      <geometry>
        <box size="2.5 0.75 0.1" />
      </geometry>
      <material name="base_link-material">
        <color rgba="0.05 0.05 0.05 1" />
      </material>
    </visual>
    <collision>
      <origin xyz="0 0 0" rpy="0 0 0" />
      <geometry>
        <box size="2.5 0.75 0.1" />
      </geometry>
    </collision>
    <inertial>
      <origin xyz="0 0 0" rpy="0 0 0" />
      <mass value="100" />
      <inertia ixx="10" ixy="0" ixz="0" iyy="10" iyz="0" izz="10" />
    </inertial>
  </link>

  <joint name="base_link_to_hipFL" type="revolute">
    <parent link="base_link" />
    <child link="hipFL" />
    <origin xyz="0.75 0 0" rpy="0 0 0" />
    <axis xyz="0 1 0"/>
    <limit effort="1000.0" lower="-1" upper="1" velocity="0.5"/>
  </joint>

  <link name="hipFL">
    <visual>
      <origin xyz="0.5 0.45 0" rpy="0 0 0" />
      <geometry>
        <box size="1 0.1 0.1" />
      </geometry>
      <material name="hipFL-material">
        <color rgba="0.1 0.3 0.7 1" />
      </material>
    </visual>
    <collision>
      <origin xyz="0.5 0.45 0" rpy="0 0 0" />
      <geometry>
        <box size="1 0.1 0.1" />
      </geometry>
    </collision>
    <inertial>
      <origin xyz="0.5 0.45 0" rpy="0 0 0" />
      <mass value="5" />
      <inertia ixx="0.2" ixy="0" ixz="0" iyy="0.2" iyz="0" izz="0.2" />
    </inertial>
  </link>

  <joint name="hipFL_to_fourcheFL" type="revolute">
    <parent link="hipFL" />
    <child link="fourcheFL" />
    <origin xyz="1.25 0.45 0" rpy="0 0 0" />
    <axis xyz="-1 0 0"/>
    <limit effort="1000.0" lower="-1" upper="1" velocity="0.5"/>
  </joint>

  <link name="fourcheFL">
    <visual>
      <origin xyz="0 0 0" rpy="0 0 0" />
      <geometry>
        <box size="0.5 0.1 0.1" />
      </geometry>
      <material name="fourcheFL-material">
        <color rgba="0.4 1 0.2 1" />
      </material>
    </visual>
    <inertial>
      <origin xyz="0 0 0" rpy="0 0 0" />
      <mass value="5" />
      <inertia ixx="0.5" ixy="0" ixz="0" iyy="0.5" iyz="0" izz="0.5" />
    </inertial>
  </link>

  <joint name="fourcheFL_to_wheelFL" type="revolute">
    <parent link="fourcheFL" />
    <child link="wheelFL" />
    <origin xyz="0.25 0 0" rpy="1.570796326794897 0 0" />
    <axis xyz="0 0 1"/>
    <limit effort="1000.0"/>
  </joint>

  <link name="wheelFL">
    <visual>
      <origin xyz="0 0 0" rpy="0 0 0" />
      <geometry>
        <cylinder radius="0.4" length="0.05" />
      </geometry>
      <material name="wheelFL-material">
        <color rgba="0 0.2 0.7 1" />
      </material>
    </visual>
    <collision>
      <origin xyz="0 0 0" rpy="0 0 0" />
      <geometry>
        <cylinder radius="0.4" length="0.05" />
      </geometry>
    </collision>
    <inertial>
      <origin xyz="0 0 0" rpy="0 0 0" />
      <mass value="5" />
      <inertia ixx="0.3" ixy="0" ixz="0" iyy="0.5" iyz="0" izz="0.3" />
    </inertial>
  </link>

  <joint name="base_link_to_hipFR" type="revolute">
    <parent link="base_link" />
    <child link="hipFR" />
    <origin xyz="0.75 0 0" rpy="0 0 0" />
    <axis xyz="0 1 0"/>
    <limit effort="1000.0" lower="-1" upper="1" velocity="0.5"/>
  </joint>

  <link name="hipFR">
    <visual>
      <origin xyz="0.5 -0.45 0" rpy="0 0 0" />
      <geometry>
        <box size="1 0.1 0.1" />
      </geometry>
      <material name="hipFR-material">
        <color rgba="0 0.2 0.7 1" />
      </material>
    </visual>
    <collision>
      <origin xyz="0.5 -0.45 0" rpy="0 0 0" />
      <geometry>
        <box size="1 0.1 0.1" />
      </geometry>
    </collision>
    <inertial>
      <origin xyz="0.5 -0.45 0" rpy="0 0 0" />
      <mass value="5" />
      <inertia ixx="0.5" ixy="0" ixz="0" iyy="1" iyz="0" izz="0.5" />
    </inertial>
  </link>

  <joint name="hipFR_to_fourcheFR" type="revolute">
    <parent link="hipFR" />
    <child link="fourcheFR" />
    <origin xyz="1.25 -0.45 0" rpy="0 0 0" />
    <axis xyz="-1 0 0"/>
    <limit effort="1000.0" lower="-1" upper="1" velocity="0.5"/>
  </joint>

  <link name="fourcheFR">
    <visual>
      <origin xyz="0 0 0" rpy="0 0 0" />
      <geometry>
        <box size="0.5 0.1 0.1" />
      </geometry>
      <material name="fourcheFR-material">
        <color rgba="0.4 1 0.2 1" />
      </material>
    </visual>
    <inertial>
      <origin xyz="0 0 0" rpy="0 0 0" />
      <mass value="5" />
      <inertia ixx="1" ixy="0" ixz="0" iyy="1" iyz="0" izz="1" />
    </inertial>
  </link>

  <joint name="fourcheFR_to_wheelFR" type="revolute">
    <parent link="fourcheFR" />
    <child link="wheelFR" />
    <origin xyz="0.25 0 0" rpy="1.570796326794897 0 0" />
    <axis xyz="0 0 1"/>
    <limit effort="1000.0"/>
  </joint>

  <link name="wheelFR">
    <visual>
      <origin xyz="0 0 0" rpy="0 0 0" />
      <geometry>
        <cylinder radius="0.4" length="0.05" />
      </geometry>
      <material name="wheelFR-material">
        <color rgba="0 0.2 0.7 1" />
      </material>
    </visual>
    <collision>
      <origin xyz="0 0 0" rpy="0 0 0" />
      <geometry>
        <cylinder radius="0.4" length="0.05" />
      </geometry>
    </collision>
    <inertial>
      <origin xyz="0 0 0" rpy="0 0 0" />
      <mass value="5" />
      <inertia ixx="0.3" ixy="0" ixz="0" iyy="0.5" iyz="0" izz="0.3" />
    </inertial>
  </link>

  <joint name="base_link_to_cube5" type="fixed">
    <parent link="base_link" />
    <child link="cube5" />
    <origin xyz="-1.25 0 -0.5" rpy="0 0 0" />
  </joint>
  <link name="cube5">
    <visual>
      <origin xyz="0 0 0" rpy="0 0 0" />
      <geometry>
        <box size="0.1 0.1 1" />
      </geometry>
      <material name="cube5-material">
        <color rgba="0 0.8 0.9 1" />
      </material>
    </visual>
    <collision>
      <origin xyz="0 0 0" rpy="0 0 0" />
      <geometry>
        <box size="0.1 0.1 1" />
      </geometry>
    </collision>
    <inertial>
      <origin xyz="0 0 0" rpy="0 0 0" />
      <mass value="1" />
      <inertia ixx="0.2" ixy="0" ixz="0" iyy="0.2" iyz="0" izz="0.2" />
    </inertial>
  </link>

  <joint name="cube5_to_rearwheel" type="revolute">
    <parent link="cube5" />
    <child link="rearwheel" />
    <origin xyz="0 0 -0.5" rpy="1.570796326794897 0 0" />
    <axis xyz="0 0 1"/>
    <limit effort="1000.0"/>
  </joint>

  <link name="rearwheel">
    <visual>
      <origin xyz="0 0 0" rpy="0 0 0" />
      <geometry>
        <cylinder radius="0.5" length="0.05" />
      </geometry>
      <material name="rearwheel-material">
        <color rgba="0 0.4 0.9 1" />
      </material>
    </visual>
    <collision>
      <origin xyz="0 0 0" rpy="0 0 0" />
      <geometry>
        <cylinder radius="0.5" length="0.05" />
      </geometry>
    </collision>
    <inertial>
      <origin xyz="0 0 0" rpy="0 0 0" />
      <mass value="1" />
      <inertia ixx="0.3" ixy="0" ixz="0" iyy="0.5" iyz="0" izz="0.3" />
    </inertial>
  </link>
</robot>